<?xml version="1.0"?>
<robot xmlns:xacro="http://ros.org/wiki/xacro">

  <!-- ========== Wheel Link ========== -->
  <xacro:macro name="add_wheel" params="wheel_name parent_link x y z">
    <link name="${wheel_name}">
      <visual>
        <origin xyz="0 0 0" rpy="1.5708 0 0"/>
        <geometry>
          <cylinder radius="${wheel_radius}" length="${wheel_thickness}"/>
        </geometry>
        <material name="black">
          <color rgba="0.1 0.1 0.1 1.0"/>
        </material>
      </visual>

      <collision>
        <origin xyz="0 0 0" rpy="1.5708 0 0"/>
        <geometry>
          <cylinder radius="${wheel_radius}" length="${wheel_thickness}"/>
        </geometry>
      </collision>

      <inertial>
        <mass value="${wheel_mass}"/>
        <origin xyz="0 0 0" rpy="0 0 0"/>
        <inertia
          ixx="0.001" ixy="0.0" ixz="0.0"
          iyy="0.001" iyz="0.0"
          izz="0.001"/>
      </inertial>
    </link>

    <!-- Revolute joint -->
    <joint name="${wheel_name}_joint" type="continuous">
      <parent link="${parent_link}"/>
      <child link="${wheel_name}"/>
      <origin xyz="${x} ${y} ${z}" rpy="0 0 0"/>
      <axis xyz="0 1 0"/>
      <limit effort="10.0" velocity="10.0"/>
      <dynamics damping="0.1" friction="0.1"/>
    </joint>
  </xacro:macro>

</robot>
