<sdf version='1.11'>
  <model name='my_robot'>
    <link name='base_link'>
      <inertial>
        <pose>0 0 0.0013157894736842109 0 0 0</pose>
        <mass>6.46</mass>
        <inertia>
          <ixx>0.051433815789473689</ixx>
          <ixy>0</ixy>
          <ixz>0</ixz>
          <iyy>0.15168381578947371</iyy>
          <iyz>0</iyz>
          <izz>0.19047</izz>
        </inertia>
      </inertial>
      <collision name='base_link_collision'>
        <pose>0 0 0.050000000000000003 0 0 0</pose>
        <geometry>
          <box>
            <size>0.5 0.29999999999999999 0.10000000000000001</size>
          </box>
        </geometry>
      </collision>
      <collision name='base_link_fixed_joint_lump__front_caster_collision_1'>
        <pose>0.22500000000000001 0 0 0 0 0</pose>
        <geometry>
          <sphere>
            <radius>0.025000000000000001</radius>
          </sphere>
        </geometry>
      </collision>
      <collision name='base_link_fixed_joint_lump__imu_link_collision_2'>
        <pose>0 0 0.10000000000000001 0 0 0</pose>
        <geometry>
          <box>
            <size>0.040000000000000001 0.040000000000000001 0.01</size>
          </box>
        </geometry>
      </collision>
      <collision name='base_link_fixed_joint_lump__lidar_link_collision_3'>
        <pose>0 0 0.14999999999999999 0 0 0</pose>
        <geometry>
          <cylinder>
            <length>0.040000000000000001</length>
            <radius>0.050000000000000003</radius>
          </cylinder>
        </geometry>
      </collision>
      <collision name='base_link_fixed_joint_lump__rear_caster_collision_4'>
        <pose>-0.22500000000000001 0 0 0 0 0</pose>
        <geometry>
          <sphere>
            <radius>0.025000000000000001</radius>
          </sphere>
        </geometry>
      </collision>
      <visual name='base_link_visual'>
        <pose>0 0 0.050000000000000003 0 0 0</pose>
        <geometry>
          <box>
            <size>0.5 0.29999999999999999 0.10000000000000001</size>
          </box>
        </geometry>
        <material>
          <diffuse>0.125 0.75000006 1 1</diffuse>
          <ambient>0.125 0.75000006 1 1</ambient>
        </material>
      </visual>
      <visual name='base_link_fixed_joint_lump__front_caster_visual_1'>
        <pose>0.22500000000000001 0 0 0 0 0</pose>
        <geometry>
          <sphere>
            <radius>0.025000000000000001</radius>
          </sphere>
        </geometry>
        <material>
          <diffuse>0.5 0.5 0.5 1</diffuse>
          <ambient>0.5 0.5 0.5 1</ambient>
        </material>
      </visual>
      <visual name='base_link_fixed_joint_lump__imu_link_visual_2'>
        <pose>0 0 0.10000000000000001 0 0 0</pose>
        <geometry>
          <box>
            <size>0.040000000000000001 0.040000000000000001 0.01</size>
          </box>
        </geometry>
        <material>
          <diffuse>0.5 0.5 0.5 1</diffuse>
          <ambient>0.5 0.5 0.5 1</ambient>
        </material>
      </visual>
      <visual name='base_link_fixed_joint_lump__lidar_link_visual_3'>
        <pose>0 0 0.14999999999999999 0 0 0</pose>
        <geometry>
          <cylinder>
            <length>0.040000000000000001</length>
            <radius>0.050000000000000003</radius>
          </cylinder>
        </geometry>
        <material>
          <diffuse>0.125 0.125 0.125 1</diffuse>
          <ambient>0.125 0.125 0.125 1</ambient>
        </material>
      </visual>
      <visual name='base_link_fixed_joint_lump__rear_caster_visual_4'>
        <pose>-0.22500000000000001 0 0 0 0 0</pose>
        <geometry>
          <sphere>
            <radius>0.025000000000000001</radius>
          </sphere>
        </geometry>
        <material>
          <diffuse>0.5 0.5 0.5 1</diffuse>
          <ambient>0.5 0.5 0.5 1</ambient>
        </material>
      </visual>
    </link>
    <joint name='left_wheel_joint' type='revolute'>
      <pose relative_to='base_link'>0 0.16 0 0 0 0</pose>
      <parent>base_link</parent>
      <child>left_wheel</child>
      <axis>
        <xyz>0 1 0</xyz>
        <limit>
          <effort>10</effort>
          <velocity>10</velocity>
          <lower>-inf</lower>
          <upper>inf</upper>
        </limit>
        <dynamics>
          <damping>0.10000000000000001</damping>
          <friction>0.10000000000000001</friction>
          <spring_reference>0</spring_reference>
          <spring_stiffness>0</spring_stiffness>
        </dynamics>
      </axis>
    </joint>
    <link name='left_wheel'>
      <pose relative_to='left_wheel_joint'>0 0 0 0 0 0</pose>
      <inertial>
        <pose>0 0 0 0 0 0</pose>
        <mass>1</mass>
        <inertia>
          <ixx>0.001</ixx>
          <ixy>0</ixy>
          <ixz>0</ixz>
          <iyy>0.001</iyy>
          <iyz>0</iyz>
          <izz>0.001</izz>
        </inertia>
      </inertial>
      <collision name='left_wheel_collision'>
        <pose>0 0 0 1.5708 0 0</pose>
        <geometry>
          <cylinder>
            <length>0.02</length>
            <radius>0.050000000000000003</radius>
          </cylinder>
        </geometry>
      </collision>
      <visual name='left_wheel_visual'>
        <pose>0 0 0 1.5708 0 0</pose>
        <geometry>
          <cylinder>
            <length>0.02</length>
            <radius>0.050000000000000003</radius>
          </cylinder>
        </geometry>
        <material>
          <diffuse>0.125 0.125 0.125 1</diffuse>
          <ambient>0.125 0.125 0.125 1</ambient>
        </material>
      </visual>
    </link>
    <joint name='right_wheel_joint' type='revolute'>
      <pose relative_to='base_link'>0 -0.16 0 0 0 0</pose>
      <parent>base_link</parent>
      <child>right_wheel</child>
      <axis>
        <xyz>0 1 0</xyz>
        <limit>
          <effort>10</effort>
          <velocity>10</velocity>
          <lower>-inf</lower>
          <upper>inf</upper>
        </limit>
        <dynamics>
          <damping>0.10000000000000001</damping>
          <friction>0.10000000000000001</friction>
          <spring_reference>0</spring_reference>
          <spring_stiffness>0</spring_stiffness>
        </dynamics>
      </axis>
    </joint>
    <link name='right_wheel'>
      <pose relative_to='right_wheel_joint'>0 0 0 0 0 0</pose>
      <inertial>
        <pose>0 0 0 0 0 0</pose>
        <mass>1</mass>
        <inertia>
          <ixx>0.001</ixx>
          <ixy>0</ixy>
          <ixz>0</ixz>
          <iyy>0.001</iyy>
          <iyz>0</iyz>
          <izz>0.001</izz>
        </inertia>
      </inertial>
      <collision name='right_wheel_collision'>
        <pose>0 0 0 1.5708 0 0</pose>
        <geometry>
          <cylinder>
            <length>0.02</length>
            <radius>0.050000000000000003</radius>
          </cylinder>
        </geometry>
      </collision>
      <visual name='right_wheel_visual'>
        <pose>0 0 0 1.5708 0 0</pose>
        <geometry>
          <cylinder>
            <length>0.02</length>
            <radius>0.050000000000000003</radius>
          </cylinder>
        </geometry>
        <material>
          <diffuse>0.125 0.125 0.125 1</diffuse>
          <ambient>0.125 0.125 0.125 1</ambient>
        </material>
      </visual>
    </link>
    <frame name='base_footprint_joint' attached_to='base_link'>
      <pose>0 0 -0.050000000000000003 0 0 0</pose>
    </frame>
    <frame name='base_footprint' attached_to='base_footprint_joint'>
      <pose>0 0 0 0 0 0</pose>
    </frame>
    <frame name='front_caster_joint' attached_to='base_link'>
      <pose>0.22500000000000001 0 0 0 0 0</pose>
    </frame>
    <frame name='front_caster' attached_to='front_caster_joint'>
      <pose>0 0 0 0 0 0</pose>
    </frame>
    <frame name='imu_link_joint' attached_to='base_link'>
      <pose>0 0 0.10000000000000001 0 0 0</pose>
    </frame>
    <frame name='imu_link' attached_to='imu_link_joint'>
      <pose>0 0 0 0 0 0</pose>
    </frame>
    <frame name='lidar_link_joint' attached_to='base_link'>
      <pose>0 0 0.14999999999999999 0 0 0</pose>
    </frame>
    <frame name='lidar_link' attached_to='lidar_link_joint'>
      <pose>0 0 0 0 0 0</pose>
    </frame>
    <frame name='rear_caster_joint' attached_to='base_link'>
      <pose>-0.22500000000000001 0 0 0 0 0</pose>
    </frame>
    <frame name='rear_caster' attached_to='rear_caster_joint'>
      <pose>0 0 0 0 0 0</pose>
    </frame>
  </model>
</sdf>
